Workbook

Sheet Products
A1: MANTECO PRICE RESILIENCE — Products Library
A2: ID | B2: Type (M/C) | C2: Brand | D2: Product Name | E2: Category | F2: Season | G2: Retail Price ($) | H2: Sale Price ($) | I2: Markdown % | J2: Resale Price ($) | K2: Residual % | L2: Fabric | M2: Product URL
A3: =IF(C3<>"","P"&TEXT(ROW()-2,"00"),"") | B3: Manteco | C3: MANGO | D3: Manteco wool coat with belt | E3: Coat | F3: CW26 | G3: 299.99 | H3: 179.99 | I3: 0.3 | K3: =IFERROR(IF(AND(G3<>"",J3<>""),J3/G3,""),"") | L3: 71% wool, 27% polyamide, 1% polyester, 1% acrylic | M3: https://shop.mango.com/us/en/p/women/coats/coats/manteco-wool-coat-with-belt_27011306?s=20&srsltid=AfmBOophh-hNVSgGynGZWotRf7pi8sa4NfhC8GHvuNy-RLQVJeHZNiGsHtk
A4: =IF(C4<>"","P"&TEXT(ROW()-2,"00"),"") | B4: Manteco | C4: SELECTED | D4: CAPPOTTO IN MISTO LANA | E4: Coat | F4: FW25 | G4: 279.99 | H4: 111.95 | I4: =IFERROR(IF(AND(G4<>"",H4<>""),(G4-H4)/G4,""),"") | K4: =IFERROR(IF(AND(G4<>"",J4<>""),J4/G4,""),"") | L4: 50% wool, 30% polyester, 10% scrylic, 5% polyamide, 5% other fibres | M4: https://www.zalando.it/selected-homme-cappotto-classico-dark-brown-se622t0qi-o11.html?ssku=SE622T0QI-O11000L000&lang=it&otid=default&wmc=SEM390_NB_GO._8690582122_680648580_34341989185.&opc=2211&mpp=google%7Cv1%7C%7Cpla-18283950120%7C%7C9202131%7C%7Cg%7Cc%7C%7C149792249252%7C%7Cpla%7CSE622T0QI-O11000L000%7C18283950120%7C1%7C&gclsrc=aw.ds&gad_source=1&gad_campaignid=680648580&gbraid=0AAAAADM14zeiGz97KKtkiqJ-SY9cZJKS_&gclid=CjwKCAjwhe3OBhABEiwA6392zC1Z6N9WI09HN1yILD4-CkWOHdxo4jkZ0Q1xU54XnDeeCsZUOnEp8RoClykQAvD_BwE
A5: =IF(C5<>"","P"&TEXT(ROW()-2,"00"),"") | B5: Manteco | C5: EAVES | D5: Yaron Manteco Wool Coat | E5: Coat | F5: CW26 | G5: 495 | H5: 421 | I5: =IFERROR(IF(AND(G5<>"",H5<>""),(G5-H5)/G5,""),"") | K5: =IFERROR(IF(AND(G5<>"",J5<>""),J5/G5,""),"") | L5: 50% wool, 30% polyester, 10% acrylic, 5% nylon, 5% other fibers | M5: https://www.revolve.com/eaves-yaron-manteco-wool-coat-in-light-grey/dp/EAVR-WO139/?d=F&tCurrency=USD&tCountryCode=US&tCurrency=USD&tCountryCode=US&deeplink=true&utm_source=google&utm_medium=cpc&utm_campaign=PMax:+Product+Listing+Ads+-+PLA+-+Owned+Brands&gclsrc=aw.ds&gad_source=1&gad_campaignid=21247993676&gbraid=0AAAAAD9qhJissu2DylkCPd5PipPVYsRyp&gclid=Cj0KCQjwj47OBhCmARIsAF5wUEFhLB712EGV_Y-nwUBdthsbuj-B6UOgV_N2rKHTBzAQsnewyb4F4jgaAnaHEALw_wcB
A6: =IF(C6<>"","P"&TEXT(ROW()-2,"00"),"") | B6: Manteco | C6: EAVES | D6: x Coco Oak Manteco Wool Blazer Jacket | E6: Jacket | F6: FW25 | G6: 499 | H6: 160 | I6: =IFERROR(IF(AND(G6<>"",H6<>""),(G6-H6)/G6,""),"") | K6: =IFERROR(IF(AND(G6<>"",J6<>""),J6/G6,""),"") | L6: 50% wool, 30% polyester, 10% acrylic, 10% polyamide | M6: https://www.revolve.com/eaves-x-coco-oak-manteco-wool-blazer-jacket-in-dark-grey/dp/EAVR-WO183/?d=F&tCurrency=USD&tCountryCode=US&tCurrency=USD&tCountryCode=US&deeplink=true&utm_source=google&utm_medium=cpc&utm_campaign=Product+Listing+Ads+-+PMAX+-+Zombies&gclsrc=aw.ds&gad_source=1&gad_campaignid=20232795775&gbraid=0AAAAAD9qhJjEotflWpZQoQm6Gd6h5g9Hj&gclid=Cj0KCQjwj47OBhCmARIsAF5wUEEtPHwVvPzIv9QjjiUjMvE4DZrhnwfmTbq37rJT-icLtxXihLBiwR4aApvnEALw_wcB
A7: =IF(C7<>"","P"&TEXT(ROW()-2,"00"),"") | B7: Manteco | C7: MANGO | D7: Manteco wool coat with fur collar | E7: Coat | F7: CW26 | G7: 329 | H7: 249.99 | I7: =IFERROR(IF(AND(G7<>"",H7<>""),(G7-H7)/G7,""),"") | K7: =IFERROR(IF(AND(G7<>"",J7<>""),J7/G7,""),"") | L7: 71% wool, 26% polyamide, 1% polyester, 1% cotton, 1% acrylic | M7: https://shop.mango.com/gh/en/p/women/coats/coats/manteco-wool-coat-with-fur-collar_27031309
A8: =IF(C8<>"","P"&TEXT(ROW()-2,"00"),"") | B8: Manteco | C8: MANGO | D8: Manteco wool coat with lapels | E8: Coat | F8: CW26 | G8: 349.99 | H8: 149.99 | I8: =IFERROR(IF(AND(G8<>"",H8<>""),(G8-H8)/G8,""),"") | K8: =IFERROR(IF(AND(G8<>"",J8<>""),J8/G8,""),"") | L8: 60% virgin wool, 25% polyamide, 15% wool | M8: https://shop.mango.com/us/en/p/women/coats/coats/manteco-wool-coat-with-lapels_17016360?s=21&srsltid=AfmBOoqU_n1U9wZwRw-7PFSW3U7GOHA64XNR6QmQ2CtE4GE3U5R8iTd0B54
A9: =IF(C9<>"","P"&TEXT(ROW()-2,"00"),"") | B9: Manteco | C9: Fortela | D9: Bobbie Giacca Classica Doppiopetto In Flanella | E9: Jacket | F9: FW25 | G9: 800 | H9: 800 | I9: =IFERROR(IF(AND(G9<>"",H9<>""),(G9-H9)/G9,""),"") | K9: =IFERROR(IF(AND(G9<>"",J9<>""),J9/G9,""),"") | L9: 100% Wool | M9: https://www.fortela.com/collections/tailleur-e-giacche-donna/products/wbobbie-ma388-cam
A10: =IF(C10<>"","P"&TEXT(ROW()-2,"00"),"") | B10: Manteco | C10: MANGO | D10: Men's Manteco wool coat with lapels | E10: Coat | F10: CW26 | G10: 399 | H10: 279 | I10: =IFERROR(IF(AND(G10<>"",H10<>""),(G10-H10)/G10,""),"") | K10: =IFERROR(IF(AND(G10<>"",J10<>""),J10/G10,""),"") | L10: 75% wool, 25% polyamide | M10: https://shop.mango.com/us/en/p/men/coats/coats/manteco-wool-coat-with-lapels_27061172?s=23&srsltid=AfmBOopLb77GpDXg0uY2klNkf9_KcmgC6ZscAQi_q6H5O2aZWPe2PeOJkE8
A11: =IF(C11<>"","P"&TEXT(ROW()-2,"00"),"") | B11: Manteco | C11: Zara | D11: STRAIGHT COAT WITH MANTECO WOOL ZW COLLECTION | E11: Coat | F11: CW26 | G11: 299 | H11: 299 | I11: =IFERROR(IF(AND(G11<>"",H11<>""),(G11-H11)/G11,""),"") | K11: =IFERROR(IF(AND(G11<>"",J11<>""),J11/G11,""),"") | L11: 57% wool 29% polyamide 14% alpaca | M11: https://www.zara.com/us/en/straight-coat-with-manteco-wool-zw-collection-p02046894.html
A12: =IF(C12<>"","P"&TEXT(ROW()-2,"00"),"") | B12: Control | C12: Zara | D12: WOOL BLEND SHORT COAT ZW COLLECTION | E12: Coat | F12: CW26 | G12: 169 | H12: 169 | I12: =IFERROR(IF(AND(G12<>"",H12<>""),(G12-H12)/G12,""),"") | K12: =IFERROR(IF(AND(G12<>"",J12<>""),J12/G12,""),"") | L12: 57% wool 38% polyester 5% other fibres | M12: https://www.zara.com/us/en/zw-collection-short-wool-coat-p07522244.html
A13: =IF(C13<>"","P"&TEXT(ROW()-2,"00"),"") | B13: Manteco | C13: Zara | D13: MANTECO® ORIGINS WATER REPELLENT TRENCH COAT | E13: Coat | F13: CW26 | G13: 229 | H13: 229 | I13: =IFERROR(IF(AND(G13<>"",H13<>""),(G13-H13)/G13,""),"") | K13: =IFERROR(IF(AND(G13<>"",J13<>""),J13/G13,""),"") | L13: OUTER SHELL 100% cotton LINING 52% viscose 48% polyester | M13: https://www.zara.com/us/en/manteco--origins-water-repellent-trench-coat-p04058500.html
A14: =IF(C14<>"","P"&TEXT(ROW()-2,"00"),"") | B14: Control | C14: Zara | D14: PARKA TECNICA CON GILET REMOVIBILE | E14: Coat | F14: CW26 | G14: 139 | H14: 139 | I14: =IFERROR(IF(AND(G14<>"",H14<>""),(G14-H14)/G14,""),"") | K14: =IFERROR(IF(AND(G14<>"",J14<>""),J14/G14,""),"") | L14: ESTERNO 100% poliammide FODERA 100% cotone | M14: https://www.zara.com/it/it/parka-tecnica-con-gilet-removibile-p03918248.html?v1=503348479
A15: =IF(C15<>"","P"&TEXT(ROW()-2,"00"),"") | B15: Control | C15: MANGO | D15: CAPPOTTO LANA SPIGATO | E15: Coat | F15: CW26 | G15: 199.99 | H15: 99.99 | I15: =IFERROR(IF(AND(G15<>"",H15<>""),(G15-H15)/G15,""),"") | L15: Composizione: 63% lana, 32% poliestere, 2% poliammide, 2% viscosa, 1% acrilico | M15: https://shop.mango.com/it/it/p/uomo/cappotti/cappotti/cappotto-lana-spigato_27071171
A16: =IF(C16<>"","P"&TEXT(ROW()-2,"00"),"") | B16: Control | C16: MANGO | D16: Woollen coat with belt | E16: Coat | F16: CW26 | G16: 429.99 | H16: 269.99 | I16: =IFERROR(IF(AND(G16<>"",H16<>""),(G16-H16)/G16,""),"") | K16: =IFERROR(IF(AND(G16<>"",J16<>""),J16/G16,""),"") | L16: 78% virgin wool, 22% polyamide | M16: https://shop.mango.com/us/en/p/women/coats/coats/woollen-coat-with-belt_27044438
A17: =IF(C17<>"","P"&TEXT(ROW()-2,"00"),"") | B17: Manteco | C17: Woolrich | D17: 2-in-1 Sideline Parka in Manteco Recycled Wool Blend | E17: Coat | F17: CW26 | G17: 1320 | H17: 925 | I17: =IFERROR(IF(AND(G17<>"",H17<>""),(G17-H17)/G17,""),"") | K17: =IFERROR(IF(AND(G17<>"",J17<>""),J17/G17,""),"") | L17: 40% Wool, 28% Acrylic, 18% Polyester, 14% Polyamide | M17: https://www.woolrich.com/us/en/2-in-1-sideline-parka-in-manteco-recycled-wool-blend-CFWWOU0944FRUT3492_7391.html
A18: =IF(C18<>"","P"&TEXT(ROW()-2,"00"),"") | B18: Control | C18: Woolrich | D18: Coat in Recycled Italian Wool Blend | E18: Coat | F18: CW26 | G18: 1265 | H18: 885 | I18: =IFERROR(IF(AND(G18<>"",H18<>""),(G18-H18)/G18,""),"") | K18: =IFERROR(IF(AND(G18<>"",J18<>""),J18/G18,""),"") | L18: 75% Wool, 25% Polyamide | M18: https://www.woolrich.com/us/en/coat-in-recycled-italian-wool-blend-CFWOOU0827MRUT3109_1131.html
A19: =IF(C19<>"","P"&TEXT(ROW()-2,"00"),"") | B19: Manteco | C19: KarenMillen | D19: Italian Manteco Wool Blend Wrap Belted Tailored Midi Coat | E19: Coat | F19: CW26 | G19: 188 | H19: 48 | I19: =IFERROR(IF(AND(G19<>"",H19<>""),(G19-H19)/G19,""),"") | K19: =IFERROR(IF(AND(G19<>"",J19<>""),J19/G19,""),"") | L19: 50% Wool 35% Polyester 15% Polyamide | M19: https://www.karenmillen.com/product/karen-millen-italian-manteco-wool-blend-wrap-belted-tailored-midi-coat_bkk19128?colour=black
A20: P18 | B20: Control | C20: KarenMillen | D20: Wool Tailored Flared Skirt Midi Coat | E20: Coat | F20: CW26 | G20: 509 | H20: 305 | I20: =IFERROR(IF(AND(G20<>"",H20<>""),(G20-H20)/G20,""),"") | K20: =IFERROR(IF(AND(G20<>"",J20<>""),J20/G20,""),"") | L20: 52% Wool. 40% Polyester. 5% Polyamide. 2% Acrylic. 1% Viscose/Rayon | M20: https://www.karenmillen.com/product/karen-millen-wool-tailored-flared-skirt-midi-coat_bkk25973?colour=ivory
A21: =IF(C21<>"","P"&TEXT(ROW()-2,"00"),"") | B21: Manteco | C21: Zara | D21: MANTECO WOOL COAT ZW COLLECTION LIMITED EDITION | E21: Coat | F21: CW26 | G21: 269 | H21: 269 | I21: =IFERROR(IF(AND(G21<>"",H21<>""),(G21-H21)/G21,""),"") | K21: =IFERROR(IF(AND(G21<>"",J21<>""),J21/G21,""),"") | L21: 42% wool 31% lyocell 25% polyamide 2% other fibres | M21: MANTECO WOOL COAT ZW COLLECTION LIMITED EDITION - Brown / Taupe | ZARA United States
A22: =IF(C22<>"","P"&TEXT(ROW()-2,"00"),"") | B22: Control | C22: Zara | D22: CAPPOTTO DOPPIOPETTO MISTO LANA CON CINTURA | E22: Coat | F22: CW26 | G22: 99.95 | H22: 99.95 | I22: =IFERROR(IF(AND(G22<>"",H22<>""),(G22-H22)/G22,""),"") | K22: =IFERROR(IF(AND(G22<>"",J22<>""),J22/G22,""),"") | L22: ESTERNO 57% poliestere 41% lana 2% altre fibre | M22: https://www.zara.com/it/it/cappotto-doppiopetto-misto-lana-con-cintura-p02949150.html?v1=497563430&v2=2436891
A23: =IF(C23<>"","P"&TEXT(ROW()-2,"00"),"") | B23: Manteco | C23: Harrods | D23: Wool-Blend Overcoat | E23: Coat | F23: CW26 | G23: £720 | H23: £720 | I23: 0 | K23: =IFERROR(IF(AND(G23<>"",J23<>""),J23/G23,""),"") | L23: 70% Recycled Wool 30% Recycled Polyamide | M23: https://www.harrods.com/en-it/p/samsoe-samsoe-wool-blend-overcoat-000000000007888237
A24: =IF(C24<>"","P"&TEXT(ROW()-2,"00"),"") | B24: Control | C24: Toteme | D24: double-breasted wool coat | E24: Coat | F24: CW26 | G24: £1162 | H24: £1162 | I24: 0 | K24: =IFERROR(IF(AND(G24<>"",J24<>""),J24/G24,""),"") | L24: Wool 70%, Polyamide 25% | M24: https://www.farfetch.com/ro/shopping/women/toteme-double-breasted-wool-coat-item-32435140.aspx
A25: =IF(C25<>"","P"&TEXT(ROW()-2,"00"),"") | B25: Manteco | C25: Degliuberti | D25: Installation Coat | E25: Coat | F25: CW26 | G25: £850 | H25: £680 | I25: 0.2 | K25: =IFERROR(IF(AND(G25<>"",J25<>""),J25/G25,""),"") | L25: 100% recycled wool | M25: https://degliubertistore.com/products/installation-coat
A26: =IF(C26<>"","P"&TEXT(ROW()-2,"00"),"") | B26: Control | C26: DE BONNE FACTURE | D26: Camargue Wool Coat | E26: Coat | F26: CW26 | G26: £995 | H26: £995 | I26: 0 | K26: =IFERROR(IF(AND(G26<>"",J26<>""),J26/G26,""),"") | L26: 100% wool | M26: https://www.mrporter.com/en-it/mens/product/de-bonne-facture/clothing/winter-coats/camargue-wool-coat/46376663162915350
A27: =IF(C27<>"","P"&TEXT(ROW()-2,"00"),"") | B27: Manteco | C27: Isto | D27: RECYCLED WOOL WORK JACKET | E27: Coat | F27: CW26 | G27: 300 | H27: 150 | I27: =IFERROR(IF(AND(G27<>"",H27<>""),(G27-H27)/G27,""),"") | K27: =IFERROR(IF(AND(G27<>"",J27<>""),J27/G27,""),"") | L27: 100% Recycled Wool | M27: https://isto.pt/products/recycled-wool-work-jacket-navy?country=US
A28: =IF(C28<>"","P"&TEXT(ROW()-2,"00"),"") | B28: Control | C28: Frame | D28: Wool Chore Jacket | E28: Coat | F28: CW26 | G28: 650 | H28: 325 | I28: =IFERROR(IF(AND(G28<>"",H28<>""),(G28-H28)/G28,""),"") | K28: =IFERROR(IF(AND(G28<>"",J28<>""),J28/G28,""),"") | L28: 100% wool | M28: https://www.mrporter.com/en-us/mens/product/frame/clothing/lightweight-waterproof-jackets/wool-chore-jacket/1647597356004941
A29: =IF(C29<>"","P"&TEXT(ROW()-2,"00"),"") | B29: Manteco | C29: Zero Barra Cento | D29: Soft Short Recycled Wool Trench Coat | E29: Coat | F29: CW26 | G29: 466.56 | H29: 466.56 | I29: =IFERROR(IF(AND(G29<>"",H29<>""),(G29-H29)/G29,""),"") | K29: =IFERROR(IF(AND(G29<>"",J29<>""),J29/G29,""),"") | L29: 70% wool, 30% polyamide | M29: https://zerobarracento.com/products/soft-short-recycled-wool-trench-coat
A30: =IF(C30<>"","P"&TEXT(ROW()-2,"00"),"") | B30: Control | C30: Officine Generale | D30: Aretha Coat | E30: Coat | F30: CW26 | G30: £903 | H30: £495 | I30: 0.45182724 | K30: =IFERROR(IF(AND(G30<>"",J30<>""),J30/G30,""),"") | L30: Virgin Wool 60%, Polyester 20%, Polyamide 15%, other fibers 5% | M30: https://www.farfetch.com/cz/shopping/women/officine-generale-aretha-coat-item-25126877.aspx
A31: P29 | B31: Manteco | C31: Aritzia | D31: Portfolio Double Face Coat | E31: Coat | F31: CW26 | G31: 378 | H31: 118 | I31: 0.68783069 | K31: =IFERROR(IF(AND(G31<>"",J31<>""),J31/G31,""),"") | L31: 98% wool, 2% other fibres; Sleeve Lining: 100% cupro | M31: https://www.aritzia.com/intl/en/product/portfolio-double-face-coat/111630.html?color=4425
A32: P30 | B32: Control | C32: Universal Standard | D32: Double Face Luxe Coat | E32: Coat | F32: CW26 | G32: 388 | H32: 155 | I32: =IFERROR(IF(AND(G32<>"",H32<>""),(G32-H32)/G32,""),"") | K32: =IFERROR(IF(AND(G32<>"",J32<>""),J32/G32,""),"") | L32: 50% Wool 50% Polyester | M32: https://www.universalstandard.com/products/double-face-luxe-coat-black?srsltid=AfmBOopj1J3srOFjBCEJsvZeSOjm57EI1IEMRTLMLBmFJ3PIoybvQFGB#:~:text=Fabric
A33: P31 | B33: Manteco | C33: Cyrillus | D33: MANTEAU CABAN LAINAGE UNI FEMME | E33: Coat | F33: CW26 | G33: 300 | H33: 300 | I33: =IFERROR(IF(AND(G33<>"",H33<>""),(G33-H33)/G33,""),"") | K33: =IFERROR(IF(AND(G33<>"",J33<>""),J33/G33,""),"") | L33: Lainage 70% laine recyclée, 30% polyamide. Doublure 100% polyester recyclé. | M33: https://cyrillus.com/products/manteau-manteau-gris-chine-fonce_7033
A34: P32 | B34: Control | C34: Vestiere Collective | D34: Massimo Dutti-Capotto in lana | E34: Coat | F34: FW25 | G34: 434 | H34: 434 | I34: =IFERROR(IF(AND(G34<>"",H34<>""),(G34-H34)/G34,""),"") | K34: =IFERROR(IF(AND(G34<>"",J34<>""),J34/G34,""),"") | L34: 70% wool, 30% polyamide | M34: https://it.vestiairecollective.com/donna-abbigliamento/cappotti/massimo-dutti/cappotti-massimo-dutti-rosa-lana-54936609.shtml
A35: P33 | B35: Manteco | C35: COS | D35: WOOL-BLEND LONG TRENCH COAT | E35: Trench | F35: FW25 | G35: 299 | H35: 299 | I35: =IFERROR(IF(AND(G35<>"",H35<>""),(G35-H35)/G35,""),"") | K35: =IFERROR(IF(AND(G35<>"",J35<>""),J35/G35,""),"") | L35: 70% Recycled wool, 30% Recycled polyamide (Recycled nylon). Lining: 100% Viscose | M35: https://www.cos.com/en-eu/women/womenswear/coatsjackets/coats/product/wool-blend-trench-coat-navy-1308449002
A36: P34 | B36: Manteco | C36: COS | D36: OVERSIZED DOUBLE-BREASTED WOOL LONG COAT | E36: Coat | F36: CW26 | G36: 449 | H36: 449 | I36: =IFERROR(IF(AND(G36<>"",H36<>""),(G36-H36)/G36,""),"") | K36: =IFERROR(IF(AND(G36<>"",J36<>""),J36/G36,""),"") | L36: 75% Recycled wool, 25% Recycled polyamide (Recycled nylon). | M36: https://www.cos.com/en-us/women/womenswear/coatsjackets/coats/product/oversized-double-breasted-wool-coat-camel-1298577004
A37: P35 | B37: Manteco | C37: Fortela | D37: Fortela Winston Double-Breasted Checked Wool Coat | E37: Coat | F37: CW26 | G37: 1740 | H37: 1740 | I37: =IFERROR(IF(AND(G37<>"",H37<>""),(G37-H37)/G37,""),"") | K37: =IFERROR(IF(AND(G37<>"",J37<>""),J37/G37,""),"") | L37: 70% wool, 30% polyamide | M37: https://www.thecoolhour.com/products/fortela-winston-double-breasted-checked-wool-coat/#:~:text=%2A%2070,wearing%20size%2050
A38: P36 | B38: Control | C38: Dries Van Noten | D38: Black Wool Coat | E38: Coat | F38: CW26 | G38: 2235 | H38: 782 | I38: =IFERROR(IF(AND(G38<>"",H38<>""),(G38-H38)/G38,""),"") | K38: =IFERROR(IF(AND(G38<>"",J38<>""),J38/G38,""),"") | L38: 70% wool, 30% polyamide. Lining 1: 100% viscose. | M38: https://www.ssense.com/en-us/women/product/dries-van-noten/black-wool-coat/18387891
A39: P37 | B39: Control | C39: NN07 | D39: Alban 8447 Wool-Blend Felt Jacket | E39: Jacket | F39: CW26 | G39: 530 | H39: 530 | I39: =IFERROR(IF(AND(G39<>"",H39<>""),(G39-H39)/G39,""),"") | K39: =IFERROR(IF(AND(G39<>"",J39<>""),J39/G39,""),"") | L39: 70% wool, 30% recycled polyester | M39: https://www.mrporter.com/en-us/mens/product/nn07/clothing/lightweight-waterproof-jackets/alban-8447-wool-blend-felt-jacket/46376663163026302?cm_mmc=PartnerizeAM-_-clothbase-_-Brand-_-1100l22433&utm_source=partnerize&utm_medium=affiliation&utm_campaign=xq_1100l22433&utm_content=clothbase&clickref=&adj_t=19hgz889&adj_campaign=xq_1100l22433
A40: P38 | B40: Control | C40: Closed | D40: Classic wool-blend coat | E40: Coat | F40: CW26 | G40: 650 | H40: 325 | I40: =IFERROR(IF(AND(G40<>"",H40<>""),(G40-H40)/G40,""),"") | K40: =IFERROR(IF(AND(G40<>"",J40<>""),J40/G40,""),"") | L40: 70% wool (recycled), 30% nylon | M40: https://www.closed.com/en/products/women-jackets-and-coats-classic-wool-blend-coat-silt-grey-c97230-66s-22-198.html
...

Sheet Matched Pairs
A1: MANTECO PRICE RESILIENCE — Matched Pairs
A2: Pair ID | B2: Brand | C2: Tier | D2: Category | E2: Season | F2: Manteco Prod. ID | G2: Control Prod. ID | H2: M: Retail ($) | I2: C: Retail ($) | J2: Premium $ | K2: Premium % | L2: Manteco Links | M2: Control Links | N2: Possible Replacements
A3: =IF(B3<>"","PA"&TEXT(ROW()-2,"00"),"") | B3: Zara | C3: Fast Fashion Premium | D3: Coat | E3: CW26 | F3: P09 | G3: P10 | H3: =IFERROR(VLOOKUP(F3,Products!A:G,7,0),"") | I3: =IFERROR(VLOOKUP(G3,Products!A:G,7,0),"") | J3: =IFERROR(IF(AND(H3<>"",I3<>""),H3-I3,""),"") | K3: =IFERROR(IF(AND(H3<>"",I3<>"",I3<>0),(H3-I3)/I3,""),"") | L3: =IFERROR(VLOOKUP(F3,Products!A:M,13,0),"") | M3: =IFERROR(VLOOKUP(G3,Products!A:M,13,0),"")
A4: =IF(B4<>"","PA"&TEXT(ROW()-2,"00"),"") | B4: Zara | C4: Fast Fashion Premium | D4: Coat | E4: CW26 | F4: P11 | G4: P12 | H4: =IFERROR(VLOOKUP(F4,Products!A:G,7,0),"") | I4: =IFERROR(VLOOKUP(G4,Products!A:G,7,0),"") | J4: =IFERROR(IF(AND(H4<>"",I4<>""),H4-I4,""),"") | K4: =IFERROR(IF(AND(H4<>"",I4<>"",I4<>0),(H4-I4)/I4,""),"") | L4: =IFERROR(VLOOKUP(F4,Products!A:M,13,0),"") | M4: =IFERROR(VLOOKUP(G4,Products!A:M,13,0),"")
A5: PA03 | B5: Zara | C5: Fast Fashion Premium | D5: Coat | E5: CW26 | F5: P19 | G5: P20 | H5: =IFERROR(VLOOKUP(F5,Products!A:G,7,0),"") | I5: =IFERROR(VLOOKUP(G5,Products!A:G,7,0),"") | J5: =IFERROR(IF(AND(H5<>"",I5<>""),H5-I5,""),"") | K5: =IFERROR(IF(AND(H5<>"",I5<>"",I5<>0),(H5-I5)/I5,""),"") | L5: https://www.zara.com/us/en/manteco-wool-coat-zw-collection-limited-edition-p02100762.html | M5: =IFERROR(VLOOKUP(G5,Products!A:M,13,0),"")
A6: PA04 | B6: Zara | C6: Fast Fashion Premium | D6: Coat | E6: CW26 | F6: P46 | G6: P62 | H6: =IFERROR(VLOOKUP(F6,Products!A:G,7,0),"") | I6: =IFERROR(VLOOKUP(G6,Products!A:G,7,0),"") | J6: =IFERROR(IF(AND(H6<>"",I6<>""),H6-I6,""),"") | K6: =IFERROR(IF(AND(H6<>"",I6<>"",I6<>0),(H6-I6)/I6,""),"") | L6: =IFERROR(VLOOKUP(F6,Products!A:M,13,0),"") | M6: =IFERROR(VLOOKUP(G6,Products!A:M,13,0),"")
A7: PA05 | B7: Mango | C7: Fast Fashion Premium | D7: Coat | E7: CW26 | F7: P01 | G7: P55 | H7: =IFERROR(VLOOKUP(F7,Products!A:G,7,0),"") | I7: =IFERROR(VLOOKUP(G7,Products!A:G,7,0),"") | J7: =IFERROR(IF(AND(H7<>"",I7<>""),H7-I7,""),"") | K7: =IFERROR(IF(AND(H7<>"",I7<>"",I7<>0),(H7-I7)/I7,""),"") | L7: =IFERROR(VLOOKUP(F7,Products!A:M,13,0),"") | M7: =IFERROR(VLOOKUP(G7,Products!A:M,13,0),"") | N7: https://shop.mango.com/us/en/p/women/coats/coats/woollen-coat-with-belt_27044438
A8: PA06 | B8: Mango | C8: Fast Fashion Premium | D8: Coat | E8: CW26 | F8: P05 | G8: P56 | H8: 329.99 | I8: =IFERROR(VLOOKUP(G8,Products!A:G,7,0),"") | J8: =IFERROR(IF(AND(H8<>"",I8<>""),H8-I8,""),"") | K8: =IFERROR(IF(AND(H8<>"",I8<>"",I8<>0),(H8-I8)/I8,""),"") | L8: =IFERROR(VLOOKUP(F8,Products!A:M,13,0),"") | M8: =IFERROR(VLOOKUP(G8,Products!A:M,13,0),"")
A9: PA07 | B9: Mango | C9: Fast Fashion Premium | D9: Coat | E9: CW26 | F9: P08 | G9: P13 | H9: =IFERROR(VLOOKUP(F9,Products!A:G,7,0),"") | I9: =IFERROR(VLOOKUP(G9,Products!A:G,7,0),"") | J9: =IFERROR(IF(AND(H9<>"",I9<>""),H9-I9,""),"") | K9: =IFERROR(IF(AND(H9<>"",I9<>"",I9<>0),(H9-I9)/I9,""),"") | L9: =IFERROR(VLOOKUP(F9,Products!A:M,13,0),"") | M9: =IFERROR(VLOOKUP(G9,Products!A:M,13,0),"") | N9: https://shop.mango.com/us/en/p/men/coats/coats/long-wool-coat_17086720?c=09
A10: PA08 | B10: H&M | C10: Fast Fashion Premium | D10: Coat | E10: CW26 | F10: P41 | G10: P50 | H10: =IFERROR(VLOOKUP(F10,Products!A:G,7,0),"") | I10: =IFERROR(VLOOKUP(G10,Products!A:G,7,0),"") | J10: =IFERROR(IF(AND(H10<>"",I10<>""),H10-I10,""),"") | K10: =IFERROR(IF(AND(H10<>"",I10<>"",I10<>0),(H10-I10)/I10,""),"") | L10: =IFERROR(VLOOKUP(F10,Products!A:M,13,0),"") | M10: =IFERROR(VLOOKUP(G10,Products!A:M,13,0),"")
A11: PA09 | B11: H&M | C11: Fast Fashion Premium | D11: Coat | E11: CW06 | F11: P42 | G11: P51 | H11: =IFERROR(VLOOKUP(F11,Products!A:G,7,0),"") | I11: =IFERROR(VLOOKUP(G11,Products!A:G,7,0),"") | J11: =IFERROR(IF(AND(H11<>"",I11<>""),H11-I11,""),"") | K11: =IFERROR(IF(AND(H11<>"",I11<>"",I11<>0),(H11-I11)/I11,""),"") | L11: =IFERROR(VLOOKUP(F11,Products!A:M,13,0),"") | M11: =IFERROR(VLOOKUP(G11,Products!A:M,13,0),"")
A12: PA10 | B12: H&M | C12: Fast Fashion Premium | D12: Coat | E12: CW06 | F12: P43 | G12: P52 | H12: =IFERROR(VLOOKUP(F12,Products!A:G,7,0),"") | I12: =IFERROR(VLOOKUP(G12,Products!A:G,7,0),"") | J12: =IFERROR(IF(AND(H12<>"",I12<>""),H12-I12,""),"") | K12: =IFERROR(IF(AND(H12<>"",I12<>"",I12<>0),(H12-I12)/I12,""),"") | L12: =IFERROR(VLOOKUP(F12,Products!A:M,13,0),"") | M12: =IFERROR(VLOOKUP(G12,Products!A:M,13,0),"")
A13: PA11 | B13: COS | C13: Contemporary Premium | D13: Coat | E13: FW25 | F13: P33 | G13: P53 | H13: =IFERROR(VLOOKUP(F13,Products!A:G,7,0),"") | I13: =IFERROR(VLOOKUP(G13,Products!A:G,7,0),"") | J13: =IFERROR(IF(AND(H13<>"",I13<>""),H13-I13,""),"") | K13: =IFERROR(IF(AND(H13<>"",I13<>"",I13<>0),(H13-I13)/I13,""),"") | L13: =IFERROR(VLOOKUP(F13,Products!A:M,13,0),"") | M13: =IFERROR(VLOOKUP(G13,Products!A:M,13,0),"")
A14: PA12 | B14: COS | C14: Contemporary Premium | D14: Trench | E14: CW26 | F14: P34 | G14: P54 | H14: =IFERROR(VLOOKUP(F14,Products!A:G,7,0),"") | I14: =IFERROR(VLOOKUP(G14,Products!A:G,7,0),"") | J14: =IFERROR(IF(AND(H14<>"",I14<>""),H14-I14,""),"") | K14: =IFERROR(IF(AND(H14<>"",I14<>"",I14<>0),(H14-I14)/I14,""),"") | L14: =IFERROR(VLOOKUP(F14,Products!A:M,13,0),"") | M14: =IFERROR(VLOOKUP(G14,Products!A:M,13,0),"")
A15: PA13 | B15: Woolrich | C15: Contemporary Premium | D15: Coat | E15: CW26 | F15: P15 | G15: P16 | H15: =IFERROR(VLOOKUP(F15,Products!A:G,7,0),"") | I15: =IFERROR(VLOOKUP(G15,Products!A:G,7,0),"") | J15: =IFERROR(IF(AND(H15<>"",I15<>""),H15-I15,""),"") | K15: =IFERROR(IF(AND(H15<>"",I15<>"",I15<>0),(H15-I15)/I15,""),"") | L15: =IFERROR(VLOOKUP(F15,Products!A:M,13,0),"") | M15: =IFERROR(VLOOKUP(G15,Products!A:M,13,0),"")
A16: PA14 | B16: Karen Millen | C16: Contemporary Premium | D16: Coat | E16: CW26 | F16: P17 | G16: P18 | H16: =IFERROR(VLOOKUP(F16,Products!A:G,7,0),"") | I16: =IFERROR(VLOOKUP(G16,Products!A:G,7,0),"") | J16: =IFERROR(IF(AND(H16<>"",I16<>""),H16-I16,""),"") | K16: =IFERROR(IF(AND(H16<>"",I16<>"",I16<>0),(H16-I16)/I16,""),"") | L16: =IFERROR(VLOOKUP(F16,Products!A:M,13,0),"") | M16: =IFERROR(VLOOKUP(G16,Products!A:M,13,0),"")
A17: PA15 | B17: Aritzia | C17: Contemporary Premium | D17: Coat | E17: CW26 | F17: P29 | G17: P58 | H17: =IFERROR(VLOOKUP(F17,Products!A:G,7,0),"") | I17: =IFERROR(VLOOKUP(G17,Products!A:G,7,0),"") | J17: =IFERROR(IF(AND(H17<>"",I17<>""),H17-I17,""),"") | K17: =IFERROR(IF(AND(H17<>"",I17<>"",I17<>0),(H17-I17)/I17,""),"") | L17: =IFERROR(VLOOKUP(F17,Products!A:M,13,0),"") | M17: =IFERROR(VLOOKUP(G17,Products!A:M,13,0),"")
A18: PA16 | B18: Fortela | C18: Contemporary Premium | D18: Coat | E18: CW16 | F18: P07 | G18: P59 | H18: =IFERROR(VLOOKUP(F18,Products!A:G,7,0),"") | I18: =IFERROR(VLOOKUP(G18,Products!A:G,7,0),"") | J18: =IFERROR(IF(AND(H18<>"",I18<>""),H18-I18,""),"") | K18: =IFERROR(IF(AND(H18<>"",I18<>"",I18<>0),(H18-I18)/I18,""),"") | L18: =IFERROR(VLOOKUP(F18,Products!A:M,13,0),"") | M18: =IFERROR(VLOOKUP(G18,Products!A:M,13,0),"")
A19: PA17 | B19: Selected | C19: Contemporary Premium | D19: Jacket | E19: FW25 | F19: P02 | G19: P60 | H19: =IFERROR(VLOOKUP(F19,Products!A:G,7,0),"") | I19: =IFERROR(VLOOKUP(G19,Products!A:G,7,0),"") | J19: =IFERROR(IF(AND(H19<>"",I19<>""),H19-I19,""),"") | K19: =IFERROR(IF(AND(H19<>"",I19<>"",I19<>0),(H19-I19)/I19,""),"") | L19: =IFERROR(VLOOKUP(F19,Products!A:M,13,0),"") | M19: =IFERROR(VLOOKUP(G19,Products!A:M,13,0),"")
A20: PA18 | B20: Selected | C20: Contemporary Premium | D20: Coat | E20: CW26 | F20: P44 | G20: P61 | H20: =IFERROR(VLOOKUP(F20,Products!A:G,7,0),"") | I20: =IFERROR(VLOOKUP(G20,Products!A:G,7,0),"") | J20: =IFERROR(IF(AND(H20<>"",I20<>""),H20-I20,""),"") | K20: =IFERROR(IF(AND(H20<>"",I20<>"",I20<>0),(H20-I20)/I20,""),"") | L20: =IFERROR(VLOOKUP(F20,Products!A:M,13,0),"") | M20: =IFERROR(VLOOKUP(G20,Products!A:M,13,0),"")
A21: PA19 | B21: Zara | C21: Fast Fashion Premium | D21: Coat | E21: CW26 | F21: P19 | G21: P57 | H21: 269 | I21: =IFERROR(VLOOKUP(G21,Products!A:G,7,0),"") | J21: =IFERROR(IF(AND(H21<>"",I21<>""),H21-I21,""),"") | K21: =IFERROR(IF(AND(H21<>"",I21<>"",I21<>0),(H21-I21)/I21,""),"") | L21: https://www.zara.com/us/en/manteco-wool-coat-zw-collection-limited-edition-p02100762.html | M21: https://www.zara.com/it/it/cappotto-corto-misto-lana-con-collo-alto-p02077323.html?v1=498022789&v2=2419020
A22: PA20 | B22: Mango | C22: Fast Fashion Premium | D22: Coat | E22: CW26 | F22: P06 | G22: P13 | H22: =IFERROR(VLOOKUP(F22,Products!A:G,7,0),"") | I22: =IFERROR(VLOOKUP(G22,Products!A:G,7,0),"") | J22: =IFERROR(IF(AND(H22<>"",I22<>""),H22-I22,""),"") | K22: =IFERROR(IF(AND(H22<>"",I22<>"",I22<>0),(H22-I22)/I22,""),"") | L22: =IFERROR(VLOOKUP(F22,Products!A:M,13,0),"") | M22: =IFERROR(VLOOKUP(G22,Products!A:M,13,0),"") | N22: https://shop.mango.com/us/en/p/women/coats/coats/double-breasted-wool-coat_27093325
A23: =IF(B23<>"","PA"&TEXT(ROW()-2,"00"),"") | H23: =IFERROR(VLOOKUP(F23,Products!A:G,7,0),"") | I23: =IFERROR(VLOOKUP(G23,Products!A:G,7,0),"") | J23: =IFERROR(IF(AND(H23<>"",I23<>""),H23-I23,""),"") | K23: =IFERROR(IF(AND(H23<>"",I23<>"",I23<>0),(H23-I23)/I23,""),"")
A24: =IF(B24<>"","PA"&TEXT(ROW()-2,"00"),"") | H24: =IFERROR(VLOOKUP(F24,Products!A:G,7,0),"") | I24: =IFERROR(VLOOKUP(G24,Products!A:G,7,0),"") | J24: =IFERROR(IF(AND(H24<>"",I24<>""),H24-I24,""),"") | K24: =IFERROR(IF(AND(H24<>"",I24<>"",I24<>0),(H24-I24)/I24,""),"")
A25: =IF(B25<>"","PA"&TEXT(ROW()-2,"00"),"") | H25: =IFERROR(VLOOKUP(F25,Products!A:G,7,0),"") | I25: =IFERROR(VLOOKUP(G25,Products!A:G,7,0),"") | J25: =IFERROR(IF(AND(H25<>"",I25<>""),H25-I25,""),"") | K25: =IFERROR(IF(AND(H25<>"",I25<>"",I25<>0),(H25-I25)/I25,""),"")
A26: =IF(B26<>"","PA"&TEXT(ROW()-2,"00"),"") | H26: =IFERROR(VLOOKUP(F26,Products!A:G,7,0),"") | I26: =IFERROR(VLOOKUP(G26,Products!A:G,7,0),"") | J26: =IFERROR(IF(AND(H26<>"",I26<>""),H26-I26,""),"") | K26: =IFERROR(IF(AND(H26<>"",I26<>"",I26<>0),(H26-I26)/I26,""),"")
A27: =IF(B27<>"","PA"&TEXT(ROW()-2,"00"),"") | H27: =IFERROR(VLOOKUP(F27,Products!A:G,7,0),"") | I27: =IFERROR(VLOOKUP(G27,Products!A:G,7,0),"") | J27: =IFERROR(IF(AND(H27<>"",I27<>""),H27-I27,""),"") | K27: =IFERROR(IF(AND(H27<>"",I27<>"",I27<>0),(H27-I27)/I27,""),"")
A28: =IF(B28<>"","PA"&TEXT(ROW()-2,"00"),"") | H28: =IFERROR(VLOOKUP(F28,Products!A:G,7,0),"") | I28: =IFERROR(VLOOKUP(G28,Products!A:G,7,0),"") | J28: =IFERROR(IF(AND(H28<>"",I28<>""),H28-I28,""),"") | K28: =IFERROR(IF(AND(H28<>"",I28<>"",I28<>0),(H28-I28)/I28,""),"")
A29: =IF(B29<>"","PA"&TEXT(ROW()-2,"00"),"") | H29: =IFERROR(VLOOKUP(F29,Products!A:G,7,0),"") | I29: =IFERROR(VLOOKUP(G29,Products!A:G,7,0),"") | J29: =IFERROR(IF(AND(H29<>"",I29<>""),H29-I29,""),"") | K29: =IFERROR(IF(AND(H29<>"",I29<>"",I29<>0),(H29-I29)/I29,""),"")
A30: =IF(B30<>"","PA"&TEXT(ROW()-2,"00"),"") | H30: =IFERROR(VLOOKUP(F30,Products!A:G,7,0),"") | I30: =IFERROR(VLOOKUP(G30,Products!A:G,7,0),"") | J30: =IFERROR(IF(AND(H30<>"",I30<>""),H30-I30,""),"") | K30: =IFERROR(IF(AND(H30<>"",I30<>"",I30<>0),(H30-I30)/I30,""),"")
A31: =IF(B31<>"","PA"&TEXT(ROW()-2,"00"),"") | H31: =IFERROR(VLOOKUP(F31,Products!A:G,7,0),"") | I31: =IFERROR(VLOOKUP(G31,Products!A:G,7,0),"") | J31: =IFERROR(IF(AND(H31<>"",I31<>""),H31-I31,""),"") | K31: =IFERROR(IF(AND(H31<>"",I31<>"",I31<>0),(H31-I31)/I31,""),"")
A32: =IF(B32<>"","PA"&TEXT(ROW()-2,"00"),"") | H32: =IFERROR(VLOOKUP(F32,Products!A:G,7,0),"") | I32: =IFERROR(VLOOKUP(G32,Products!A:G,7,0),"") | J32: =IFERROR(IF(AND(H32<>"",I32<>""),H32-I32,""),"") | K32: =IFERROR(IF(AND(H32<>"",I32<>"",I32<>0),(H32-I32)/I32,""),"")
A33: =IF(B33<>"","PA"&TEXT(ROW()-2,"00"),"") | H33: =IFERROR(VLOOKUP(F33,Products!A:G,7,0),"") | I33: =IFERROR(VLOOKUP(G33,Products!A:G,7,0),"") | J33: =IFERROR(IF(AND(H33<>"",I33<>""),H33-I33,""),"") | K33: =IFERROR(IF(AND(H33<>"",I33<>"",I33<>0),(H33-I33)/I33,""),"")
A34: =IF(B34<>"","PA"&TEXT(ROW()-2,"00"),"") | H34: =IFERROR(VLOOKUP(F34,Products!A:G,7,0),"") | I34: =IFERROR(VLOOKUP(G34,Products!A:G,7,0),"") | J34: =IFERROR(IF(AND(H34<>"",I34<>""),H34-I34,""),"") | K34: =IFERROR(IF(AND(H34<>"",I34<>"",I34<>0),(H34-I34)/I34,""),"")
... A52: =IF(B52<>"","PA"&TEXT(ROW()-2,"00"),"") | H52: =IFERROR(VLOOKUP(F52,Products!A:G,7,0),"") | I52: =IFERROR(VLOOKUP(G52,Products!A:G,7,0),"") | J52: =IFERROR(IF(AND(H52<>"",I52<>""),H52-I52,""),"") | K52: =IFERROR(IF(AND(H52<>"",I52<>"",I52<>0),(H52-I52)/I52,""),"")

Sheet Markdown
A1: MANTECO PRICE RESILIENCE — Stage 3: Markdown Analysis
A2: Pair ID | B2: Brand | C2: M: Retail ($) | D2: M: Sale ($) | E2: M: MD% | F2: C: Retail ($) | G2: C: Sale ($) | H2: C: MD% | I2: Delta (pp) | J2: M: Sale URL | K2: C: Sale URL
A3: {=IFERROR(INDEX('Matched Pairs'!A:A,ROW()-1),"")} | B3: {=IFERROR(INDEX('Matched Pairs'!B:B,ROW()-1),"")} | C3: {=IFERROR(INDEX('Matched Pairs'!H:H,ROW()-1),"")} | E3: =IFERROR(IF(AND(C3<>"",D3<>""),(C3-D3)/C3,""),"") | F3: {=IFERROR(INDEX('Matched Pairs'!I:I,ROW()-1),"")} | H3: =IFERROR(IF(AND(F3<>"",G3<>""),(F3-G3)/F3,""),"") | I3: =IFERROR(IF(AND(E3<>"",H3<>""),H3-E3,""),"")
A4: {=IFERROR(INDEX('Matched Pairs'!A:A,ROW()-1),"")} | B4: {=IFERROR(INDEX('Matched Pairs'!B:B,ROW()-1),"")} | C4: {=IFERROR(INDEX('Matched Pairs'!H:H,ROW()-1),"")} | E4: =IFERROR(IF(AND(C4<>"",D4<>""),(C4-D4)/C4,""),"") | F4: {=IFERROR(INDEX('Matched Pairs'!I:I,ROW()-1),"")} | H4: =IFERROR(IF(AND(F4<>"",G4<>""),(F4-G4)/F4,""),"") | I4: =IFERROR(IF(AND(E4<>"",H4<>""),H4-E4,""),"")
A5: {=IFERROR(INDEX('Matched Pairs'!A:A,ROW()-1),"")} | B5: {=IFERROR(INDEX('Matched Pairs'!B:B,ROW()-1),"")} | C5: {=IFERROR(INDEX('Matched Pairs'!H:H,ROW()-1),"")} | E5: =IFERROR(IF(AND(C5<>"",D5<>""),(C5-D5)/C5,""),"") | F5: {=IFERROR(INDEX('Matched Pairs'!I:I,ROW()-1),"")} | H5: =IFERROR(IF(AND(F5<>"",G5<>""),(F5-G5)/F5,""),"") | I5: =IFERROR(IF(AND(E5<>"",H5<>""),H5-E5,""),"")
A6: {=IFERROR(INDEX('Matched Pairs'!A:A,ROW()-1),"")} | B6: {=IFERROR(INDEX('Matched Pairs'!B:B,ROW()-1),"")} | C6: {=IFERROR(INDEX('Matched Pairs'!H:H,ROW()-1),"")} | E6: =IFERROR(IF(AND(C6<>"",D6<>""),(C6-D6)/C6,""),"") | F6: {=IFERROR(INDEX('Matched Pairs'!I:I,ROW()-1),"")} | H6: =IFERROR(IF(AND(F6<>"",G6<>""),(F6-G6)/F6,""),"") | I6: =IFERROR(IF(AND(E6<>"",H6<>""),H6-E6,""),"")
A7: {=IFERROR(INDEX('Matched Pairs'!A:A,ROW()-1),"")} | B7: {=IFERROR(INDEX('Matched Pairs'!B:B,ROW()-1),"")} | C7: {=IFERROR(INDEX('Matched Pairs'!H:H,ROW()-1),"")} | E7: =IFERROR(IF(AND(C7<>"",D7<>""),(C7-D7)/C7,""),"") | F7: {=IFERROR(INDEX('Matched Pairs'!I:I,ROW()-1),"")} | H7: =IFERROR(IF(AND(F7<>"",G7<>""),(F7-G7)/F7,""),"") | I7: =IFERROR(IF(AND(E7<>"",H7<>""),H7-E7,""),"")
A8: {=IFERROR(INDEX('Matched Pairs'!A:A,ROW()-1),"")} | B8: {=IFERROR(INDEX('Matched Pairs'!B:B,ROW()-1),"")} | C8: {=IFERROR(INDEX('Matched Pairs'!H:H,ROW()-1),"")} | D8: 179.99 | E8: =IFERROR(IF(AND(C8<>"",D8<>""),(C8-D8)/C8,""),"") | F8: {=IFERROR(INDEX('Matched Pairs'!I:I,ROW()-1),"")} | J8: https://shop.mango.com/us/en/p/women/coats/coats/manteco-wool-coat-with-belt_27011306?s=20&srsltid=AfmBOophh-hNVSgGynGZWotRf7pi8sa4NfhC8GHvuNy-RLQVJeHZNiGsHtk
A9: {=IFERROR(INDEX('Matched Pairs'!A:A,ROW()-1),"")} | B9: {=IFERROR(INDEX('Matched Pairs'!B:B,ROW()-1),"")} | C9: {=IFERROR(INDEX('Matched Pairs'!H:H,ROW()-1),"")} | D9: 249 | E9: =IFERROR(IF(AND(C9<>"",D9<>""),(C9-D9)/C9,""),"") | F9: {=IFERROR(INDEX('Matched Pairs'!I:I,ROW()-1),"")} | G9: 119 | H9: =IFERROR(IF(AND(F9<>"",G9<>""),(F9-G9)/F9,""),"") | I9: =IFERROR(IF(AND(E9<>"",H9<>""),H9-E9,""),"") | J9: https://shop.mango.com/gh/en/p/women/coats/coats/manteco-wool-coat-with-fur-collar_27031309 | K9: https://shop.mango.com/it/it/p/donna/cappotti/cappotti/cappotto-lana-revers_17036361
A10: {=IFERROR(INDEX('Matched Pairs'!A:A,ROW()-1),"")} | B10: {=IFERROR(INDEX('Matched Pairs'!B:B,ROW()-1),"")} | C10: {=IFERROR(INDEX('Matched Pairs'!H:H,ROW()-1),"")} | D10: 279 | E10: =IFERROR(IF(AND(C10<>"",D10<>""),(C10-D10)/C10,""),"") | F10: {=IFERROR(INDEX('Matched Pairs'!I:I,ROW()-1),"")} | G10: 99.99 | H10: =IFERROR(IF(AND(F10<>"",G10<>""),(F10-G10)/F10,""),"") | I10: =IFERROR(IF(AND(E10<>"",H10<>""),H10-E10,""),"") | J10: https://shop.mango.com/us/en/p/men/coats/coats/manteco-wool-coat-with-lapels_27061172?s=23&srsltid=AfmBOopLb77GpDXg0uY2klNkf9_KcmgC6ZscAQi_q6H5O2aZWPe2PeOJkE8 | K10: https://shop.mango.com/it/it/p/uomo/cappotti/cappotti/cappotto-lana-spigato_27071171
A11: {=IFERROR(INDEX('Matched Pairs'!A:A,ROW()-1),"")} | B11: {=IFERROR(INDEX('Matched Pairs'!B:B,ROW()-1),"")} | C11: {=IFERROR(INDEX('Matched Pairs'!H:H,ROW()-1),"")} | E11: =IFERROR(IF(AND(C11<>"",D11<>""),(C11-D11)/C11,""),"") | F11: {=IFERROR(INDEX('Matched Pairs'!I:I,ROW()-1),"")} | H11: =IFERROR(IF(AND(F11<>"",G11<>""),(F11-G11)/F11,""),"") | I11: =IFERROR(IF(AND(E11<>"",H11<>""),H11-E11,""),"") | J11: https://www2.hm.com/it_it/productpage.1304699001.html?srsltid=AfmBOorTa2KQ9KsQcZIONGuI3PLEI3EDLTjKSPL-BG7AbG0WgLCviZpu
A12: {=IFERROR(INDEX('Matched Pairs'!A:A,ROW()-1),"")} | B12: {=IFERROR(INDEX('Matched Pairs'!B:B,ROW()-1),"")} | C12: {=IFERROR(INDEX('Matched Pairs'!H:H,ROW()-1),"")} | D12: 195 | E12: =IFERROR(IF(AND(C12<>"",D12<>""),(C12-D12)/C12,""),"") | F12: {=IFERROR(INDEX('Matched Pairs'!I:I,ROW()-1),"")} | H12: =IFERROR(IF(AND(F12<>"",G12<>""),(F12-G12)/F12,""),"") | I12: =IFERROR(IF(AND(E12<>"",H12<>""),H12-E12,""),"") | J12: https://www2.hm.com/it_it/productpage.1288164001.html?srsltid=AfmBOooG7v5hqupC8L_Tb_Fr4sTU0AqGL-ijdmRzqN-7BQhwwL8bLPoV
A13: {=IFERROR(INDEX('Matched Pairs'!A:A,ROW()-1),"")} | B13: {=IFERROR(INDEX('Matched Pairs'!B:B,ROW()-1),"")} | C13: {=IFERROR(INDEX('Matched Pairs'!H:H,ROW()-1),"")} | D13: 119 | E13: =IFERROR(IF(AND(C13<>"",D13<>""),(C13-D13)/C13,""),"") | F13: {=IFERROR(INDEX('Matched Pairs'!I:I,ROW()-1),"")} | H13: =IFERROR(IF(AND(F13<>"",G13<>""),(F13-G13)/F13,""),"") | I13: =IFERROR(IF(AND(E13<>"",H13<>""),H13-E13,""),"") | J13: https://www2.hm.com/it_it/productpage.1229568001.html?srsltid=AfmBOoo-lwAtdWsBO13v2DuB_Favyx5OW_Sf2mgiv_TlU5RPyoaL5fnf
A14: {=IFERROR(INDEX('Matched Pairs'!A:A,ROW()-1),"")} | B14: {=IFERROR(INDEX('Matched Pairs'!B:B,ROW()-1),"")} | C14: {=IFERROR(INDEX('Matched Pairs'!H:H,ROW()-1),"")} | E14: =IFERROR(IF(AND(C14<>"",D14<>""),(C14-D14)/C14,""),"") | F14: {=IFERROR(INDEX('Matched Pairs'!I:I,ROW()-1),"")} | H14: =IFERROR(IF(AND(F14<>"",G14<>""),(F14-G14)/F14,""),"") | I14: =IFERROR(IF(AND(E14<>"",H14<>""),H14-E14,""),"")
A15: {=IFERROR(INDEX('Matched Pairs'!A:A,ROW()-1),"")} | B15: {=IFERROR(INDEX('Matched Pairs'!B:B,ROW()-1),"")} | C15: {=IFERROR(INDEX('Matched Pairs'!H:H,ROW()-1),"")} | E15: =IFERROR(IF(AND(C15<>"",D15<>""),(C15-D15)/C15,""),"") | F15: {=IFERROR(INDEX('Matched Pairs'!I:I,ROW()-1),"")} | H15: =IFERROR(IF(AND(F15<>"",G15<>""),(F15-G15)/F15,""),"") | I15: =IFERROR(IF(AND(E15<>"",H15<>""),H15-E15,""),"")
A16: {=IFERROR(INDEX('Matched Pairs'!A:A,ROW()-1),"")} | B16: {=IFERROR(INDEX('Matched Pairs'!B:B,ROW()-1),"")} | C16: {=IFERROR(INDEX('Matched Pairs'!H:H,ROW()-1),"")} | D16: 925 | E16: =IFERROR(IF(AND(C16<>"",D16<>""),(C16-D16)/C16,""),"") | F16: {=IFERROR(INDEX('Matched Pairs'!I:I,ROW()-1),"")} | G16: 149 | H16: =IFERROR(IF(AND(F16<>"",G16<>""),(F16-G16)/F16,""),"") | I16: =IFERROR(IF(AND(E16<>"",H16<>""),H16-E16,""),"") | J16: https://www.woolrich.com/us/en/2-in-1-sideline-parka-in-manteco-recycled-wool-blend-CFWWOU0944FRUT3492_7391.html | K16: https://www.woolrich.com/it/it/giacca-a-camicia-in-misto-lana-con-motivo-a-quadri-CFWOOS2021MRUT5178_8914.html
A17: {=IFERROR(INDEX('Matched Pairs'!A:A,ROW()-1),"")} | B17: {=IFERROR(INDEX('Matched Pairs'!B:B,ROW()-1),"")} | C17: {=IFERROR(INDEX('Matched Pairs'!H:H,ROW()-1),"")} | D17: 48 | E17: =IFERROR(IF(AND(C17<>"",D17<>""),(C17-D17)/C17,""),"") | F17: {=IFERROR(INDEX('Matched Pairs'!I:I,ROW()-1),"")} | G17: 305 | H17: =IFERROR(IF(AND(F17<>"",G17<>""),(F17-G17)/F17,""),"") | I17: =IFERROR(IF(AND(E17<>"",H17<>""),H17-E17,""),"") | J17: https://www.karenmillen.com/product/karen-millen-italian-manteco-wool-stitch-detail-trench-midi-coat_bkk13707?utm_source=&colour=black | K17: https://www.karenmillen.com/us/product/karen-millen-italian-wool-double-breasted-military-midi-coat_bkk21259?colour=camel
A18: {=IFERROR(INDEX('Matched Pairs'!A:A,ROW()-1),"")} | B18: {=IFERROR(INDEX('Matched Pairs'!B:B,ROW()-1),"")} | C18: {=IFERROR(INDEX('Matched Pairs'!H:H,ROW()-1),"")} | D18: 118 | E18: =IFERROR(IF(AND(C18<>"",D18<>""),(C18-D18)/C18,""),"") | F18: {=IFERROR(INDEX('Matched Pairs'!I:I,ROW()-1),"")} | H18: =IFERROR(IF(AND(F18<>"",G18<>""),(F18-G18)/F18,""),"") | I18: =IFERROR(IF(AND(E18<>"",H18<>""),H18-E18,""),"") | J18: https://www.aritzia.com/intl/en/product/portfolio-double-face-coat/111630.html?color=4425
A19: {=IFERROR(INDEX('Matched Pairs'!A:A,ROW()-1),"")} | B19: {=IFERROR(INDEX('Matched Pairs'!B:B,ROW()-1),"")} | C19: {=IFERROR(INDEX('Matched Pairs'!H:H,ROW()-1),"")} | E19: =IFERROR(IF(AND(C19<>"",D19<>""),(C19-D19)/C19,""),"") | F19: {=IFERROR(INDEX('Matched Pairs'!I:I,ROW()-1),"")} | I19: =IFERROR(IF(AND(E19<>"",H19<>""),H19-E19,""),"")
A20: {=IFERROR(INDEX('Matched Pairs'!A:A,ROW()-1),"")} | B20: {=IFERROR(INDEX('Matched Pairs'!B:B,ROW()-1),"")} | C20: {=IFERROR(INDEX('Matched Pairs'!H:H,ROW()-1),"")} | D20: 111.95 | E20: =IFERROR(IF(AND(C20<>"",D20<>""),(C20-D20)/C20,""),"") | F20: {=IFERROR(INDEX('Matched Pairs'!I:I,ROW()-1),"")} | H20: =IFERROR(IF(AND(F20<>"",G20<>""),(F20-G20)/F20,""),"") | I20: =IFERROR(IF(AND(E20<>"",H20<>""),H20-E20,""),"") | J20: https://www.selected.com/it-it/p/cappotto-in-misto-lana/16098258_Delicioso
A21: {=IFERROR(INDEX('Matched Pairs'!A:A,ROW()-1),"")} | B21: {=IFERROR(INDEX('Matched Pairs'!B:B,ROW()-1),"")} | C21: {=IFERROR(INDEX('Matched Pairs'!H:H,ROW()-1),"")} | E21: =IFERROR(IF(AND(C21<>"",D21<>""),(C21-D21)/C21,""),"") | F21: {=IFERROR(INDEX('Matched Pairs'!I:I,ROW()-1),"")} | H21: =IFERROR(IF(AND(F21<>"",G21<>""),(F21-G21)/F21,""),"") | I21: =IFERROR(IF(AND(E21<>"",H21<>""),H21-E21,""),"")
A22: {=IFERROR(INDEX('Matched Pairs'!A:A,ROW()-1),"")} | B22: {=IFERROR(INDEX('Matched Pairs'!B:B,ROW()-1),"")} | C22: {=IFERROR(INDEX('Matched Pairs'!H:H,ROW()-1),"")} | E22: =IFERROR(IF(AND(C22<>"",D22<>""),(C22-D22)/C22,""),"") | F22: {=IFERROR(INDEX('Matched Pairs'!I:I,ROW()-1),"")} | G22: 45.95 | H22: =IFERROR(IF(AND(F22<>"",G22<>""),(F22-G22)/F22,""),"") | I22: =IFERROR(IF(AND(E22<>"",H22<>""),H22-E22,""),"") | K22: https://www.zara.com/it/it/cappotto-corto-misto-lana-con-collo-alto-p02077323.html?v1=498022789&v2=2419020
A23: {=IFERROR(INDEX('Matched Pairs'!A:A,ROW()-1),"")} | B23: {=IFERROR(INDEX('Matched Pairs'!B:B,ROW()-1),"")} | C23: {=IFERROR(INDEX('Matched Pairs'!H:H,ROW()-1),"")} | D23: 149.99 | E23: =IFERROR(IF(AND(C23<>"",D23<>""),(C23-D23)/C23,""),"") | F23: {=IFERROR(INDEX('Matched Pairs'!I:I,ROW()-1),"")} | G23: 99.99 | H23: =IFERROR(IF(AND(F23<>"",G23<>""),(F23-G23)/F23,""),"") | I23: =IFERROR(IF(AND(E23<>"",H23<>""),H23-E23,""),"") | J23: https://shop.mango.com/us/en/p/women/coats/coats/manteco-wool-coat-with-lapels_17016360?s=21&srsltid=AfmBOoqU_n1U9wZwRw-7PFSW3U7GOHA64XNR6QmQ2CtE4GE3U5R8iTd0B54 | K23: https://shop.mango.com/it/it/p/uomo/cappotti/cappotti/cappotto-lana-spigato_27071171
A24: {=IFERROR(INDEX('Matched Pairs'!A:A,ROW()-1),"")} | B24: {=IFERROR(INDEX('Matched Pairs'!B:B,ROW()-1),"")} | C24: {=IFERROR(INDEX('Matched Pairs'!H:H,ROW()-1),"")} | E24: =IFERROR(IF(AND(C24<>"",D24<>""),(C24-D24)/C24,""),"") | F24: {=IFERROR(INDEX('Matched Pairs'!I:I,ROW()-1),"")} | H24: =IFERROR(IF(AND(F24<>"",G24<>""),(F24-G24)/F24,""),"") | I24: =IFERROR(IF(AND(E24<>"",H24<>""),H24-E24,""),"")
A25: {=IFERROR(INDEX('Matched Pairs'!A:A,ROW()-1),"")} | B25: {=IFERROR(INDEX('Matched Pairs'!B:B,ROW()-1),"")} | C25: {=IFERROR(INDEX('Matched Pairs'!H:H,ROW()-1),"")} | E25: =IFERROR(IF(AND(C25<>"",D25<>""),(C25-D25)/C25,""),"") | F25: {=IFERROR(INDEX('Matched Pairs'!I:I,ROW()-1),"")} | H25: =IFERROR(IF(AND(F25<>"",G25<>""),(F25-G25)/F25,""),"") | I25: =IFERROR(IF(AND(E25<>"",H25<>""),H25-E25,""),"")
A26: {=IFERROR(INDEX('Matched Pairs'!A:A,ROW()-1),"")} | B26: {=IFERROR(INDEX('Matched Pairs'!B:B,ROW()-1),"")} | C26: {=IFERROR(INDEX('Matched Pairs'!H:H,ROW()-1),"")} | E26: =IFERROR(IF(AND(C26<>"",D26<>""),(C26-D26)/C26,""),"") | F26: {=IFERROR(INDEX('Matched Pairs'!I:I,ROW()-1),"")} | H26: =IFERROR(IF(AND(F26<>"",G26<>""),(F26-G26)/F26,""),"") | I26: =IFERROR(IF(AND(E26<>"",H26<>""),H26-E26,""),"")
A27: {=IFERROR(INDEX('Matched Pairs'!A:A,ROW()-1),"")} | B27: {=IFERROR(INDEX('Matched Pairs'!B:B,ROW()-1),"")} | C27: {=IFERROR(INDEX('Matched Pairs'!H:H,ROW()-1),"")} | E27: =IFERROR(IF(AND(C27<>"",D27<>""),(C27-D27)/C27,""),"") | F27: {=IFERROR(INDEX('Matched Pairs'!I:I,ROW()-1),"")} | H27: =IFERROR(IF(AND(F27<>"",G27<>""),(F27-G27)/F27,""),"") | I27: =IFERROR(IF(AND(E27<>"",H27<>""),H27-E27,""),"")
A28: {=IFERROR(INDEX('Matched Pairs'!A:A,ROW()-1),"")} | B28: {=IFERROR(INDEX('Matched Pairs'!B:B,ROW()-1),"")} | C28: {=IFERROR(INDEX('Matched Pairs'!H:H,ROW()-1),"")} | E28: =IFERROR(IF(AND(C28<>"",D28<>""),(C28-D28)/C28,""),"") | F28: {=IFERROR(INDEX('Matched Pairs'!I:I,ROW()-1),"")} | H28: =IFERROR(IF(AND(F28<>"",G28<>""),(F28-G28)/F28,""),"") | I28: =IFERROR(IF(AND(E28<>"",H28<>""),H28-E28,""),"")
A29: {=IFERROR(INDEX('Matched Pairs'!A:A,ROW()-1),"")} | B29: {=IFERROR(INDEX('Matched Pairs'!B:B,ROW()-1),"")} | C29: {=IFERROR(INDEX('Matched Pairs'!H:H,ROW()-1),"")} | E29: =IFERROR(IF(AND(C29<>"",D29<>""),(C29-D29)/C29,""),"") | F29: {=IFERROR(INDEX('Matched Pairs'!I:I,ROW()-1),"")} | H29: =IFERROR(IF(AND(F29<>"",G29<>""),(F29-G29)/F29,""),"") | I29: =IFERROR(IF(AND(E29<>"",H29<>""),H29-E29,""),"")
A30: {=IFERROR(INDEX('Matched Pairs'!A:A,ROW()-1),"")} | B30: {=IFERROR(INDEX('Matched Pairs'!B:B,ROW()-1),"")} | C30: {=IFERROR(INDEX('Matched Pairs'!H:H,ROW()-1),"")} | E30: =IFERROR(IF(AND(C30<>"",D30<>""),(C30-D30)/C30,""),"") | F30: {=IFERROR(INDEX('Matched Pairs'!I:I,ROW()-1),"")} | H30: =IFERROR(IF(AND(F30<>"",G30<>""),(F30-G30)/F30,""),"") | I30: =IFERROR(IF(AND(E30<>"",H30<>""),H30-E30,""),"")
A31: {=IFERROR(INDEX('Matched Pairs'!A:A,ROW()-1),"")} | B31: {=IFERROR(INDEX('Matched Pairs'!B:B,ROW()-1),"")} | C31: {=IFERROR(INDEX('Matched Pairs'!H:H,ROW()-1),"")} | E31: =IFERROR(IF(AND(C31<>"",D31<>""),(C31-D31)/C31,""),"") | F31: {=IFERROR(INDEX('Matched Pairs'!I:I,ROW()-1),"")} | H31: =IFERROR(IF(AND(F31<>"",G31<>""),(F31-G31)/F31,""),"") | I31: =IFERROR(IF(AND(E31<>"",H31<>""),H31-E31,""),"")
A32: {=IFERROR(INDEX('Matched Pairs'!A:A,ROW()-1),"")} | B32: {=IFERROR(INDEX('Matched Pairs'!B:B,ROW()-1),"")} | C32: {=IFERROR(INDEX('Matched Pairs'!H:H,ROW()-1),"")} | E32: =IFERROR(IF(AND(C32<>"",D32<>""),(C32-D32)/C32,""),"") | F32: {=IFERROR(INDEX('Matched Pairs'!I:I,ROW()-1),"")} | H32: =IFERROR(IF(AND(F32<>"",G32<>""),(F32-G32)/F32,""),"") | I32: =IFERROR(IF(AND(E32<>"",H32<>""),H32-E32,""),"")
A33: {=IFERROR(INDEX('Matched Pairs'!A:A,ROW()-1),"")} | B33: {=IFERROR(INDEX('Matched Pairs'!B:B,ROW()-1),"")} | C33: {=IFERROR(INDEX('Matched Pairs'!H:H,ROW()-1),"")} | E33: =IFERROR(IF(AND(C33<>"",D33<>""),(C33-D33)/C33,""),"") | F33: {=IFERROR(INDEX('Matched Pairs'!I:I,ROW()-1),"")} | H33: =IFERROR(IF(AND(F33<>"",G33<>""),(F33-G33)/F33,""),"") | I33: =IFERROR(IF(AND(E33<>"",H33<>""),H33-E33,""),"")
A34: {=IFERROR(INDEX('Matched Pairs'!A:A,ROW()-1),"")} | B34: {=IFERROR(INDEX('Matched Pairs'!B:B,ROW()-1),"")} | C34: {=IFERROR(INDEX('Matched Pairs'!H:H,ROW()-1),"")} | E34: =IFERROR(IF(AND(C34<>"",D34<>""),(C34-D34)/C34,""),"") | F34: {=IFERROR(INDEX('Matched Pairs'!I:I,ROW()-1),"")} | H34: =IFERROR(IF(AND(F34<>"",G34<>""),(F34-G34)/F34,""),"") | I34: =IFERROR(IF(AND(E34<>"",H34<>""),H34-E34,""),"")
A35: {=IFERROR(INDEX('Matched Pairs'!A:A,ROW()-1),"")} | B35: {=IFERROR(INDEX('Matched Pairs'!B:B,ROW()-1),"")} | C35: {=IFERROR(INDEX('Matched Pairs'!H:H,ROW()-1),"")} | E35: =IFERROR(IF(AND(C35<>"",D35<>""),(C35-D35)/C35,""),"") | F35: {=IFERROR(INDEX('Matched Pairs'!I:I,ROW()-1),"")} | H35: =IFERROR(IF(AND(F35<>"",G35<>""),(F35-G35)/F35,""),"") | I35: =IFERROR(IF(AND(E35<>"",H35<>""),H35-E35,""),"")
... A52: {=IFERROR(INDEX('Matched Pairs'!A:A,ROW()-1),"")} | B52: {=IFERROR(INDEX('Matched Pairs'!B:B,ROW()-1),"")} | C52: {=IFERROR(INDEX('Matched Pairs'!H:H,ROW()-1),"")} | E52: =IFERROR(IF(AND(C52<>"",D52<>""),(C52-D52)/C52,""),"") | F52: {=IFERROR(INDEX('Matched Pairs'!I:I,ROW()-1),"")} | H52: =IFERROR(IF(AND(F52<>"",G52<>""),(F52-G52)/F52,""),"") | I52: =IFERROR(IF(AND(E52<>"",H52<>""),H52-E52,""),"")

Sheet Resale
A1: MANTECO PRICE RESILIENCE — Stage 4: Resale Tracker
A2: Pair ID | B2: Side (M/C) | C2: Platform | D2: Original Retail ($) | E2: Resale Price ($) | F2: Residual % | G2: Age (yrs) | H2: Condition | I2: Listing Date | J2: Listing URL | K2: NOTE
A3: PA01
A4: PA01
A5: PA02
A6: PA02
A7: PA03 | B7: Manteco | C7: Vinted | D7: 269 | E7: 26.95 | F7: =IFERROR(IF(AND(D7<>"",E7<>""),E7/D7,""),"") | H7: Very Good | J7: https://www.vinted.it/items/8630741489-cappotto-blu-taglia-l-mango
A8: PA03 | F8: =IFERROR(IF(AND(D8<>"",E8<>""),E8/D8,""),"")
A9: PA04 | B9: Manteco | C9: Vinted | D9: 179 | E9: 47.95 | F9: =IFERROR(IF(AND(D9<>"",E9<>""),E9/D9,""),"") | H9: Excellent | J9: https://www.vinted.it/items/8601853893-manteco-mantel
A10: PA04 | B10: Control | C10: Vinted | D10: 149 | E10: 50 | F10: =IFERROR(IF(AND(D10<>"",E10<>""),E10/D10,""),"") | H10: Excellent | J10: https://www.vinted.it/items/8641427900-abrigo-estilo-masculino
A11: PA05 | B11: Manteco | C11: Vinted | D11: =Products!G3 | E11: 158 | F11: =IFERROR(IF(AND(D11<>"",E11<>""),E11/D11,""),"") | H11: Excellent | J11: https://www.vinted.it/items/8141310982-manteau-long-noir-mango-en-laine-manteco-70-laine?referrer=catalog
A12: PA05 | B12: Control | C12: Vinted | D12: =Products!G57 | E12: 77 | F12: =IFERROR(IF(AND(D12<>"",E12<>""),E12/D12,""),"") | H12: Excellent | J12: https://www.vinted.it/items/7394429081-cappotto-grigio-lana-spalline-taglia-sm-mango?referrer=catalog
A13: PA06 | B13: Manteco | C13: eBay | D13: =Products!G7 | E13: 220 | F13: =IFERROR(IF(AND(D13<>"",E13<>""),E13/D13,""),"") | H13: Excellent | J13: https://www.ebay.com/itm/406721971293?_skw=Manteco+wool+coat+with+fur+collar+-+mango&itmmeta=01KPBB38SRN21EKX9AGV7WZJPQ&hash=item5eb284c45d:g:2CIAAeSwcMtpn2VT&itmprp=enc%3AAQALAAABEGfYFPkwiKCW4ZNSs2u11xAEc9S1QBCZrE2GyYuEfR%2Fo%2B0MBO10SUMmL5TA60FeOxloCjaTy01VrNvaSWsPIv7019c%2F746utr1wzTDQnll2k3Jtxy3JV7T%2BOlVyWYCoMCk1s0XNzUECVa99yrahkWrvYlvFpkz%2BW4CHgV3vuk3dvJQSNsJ59iCUGsyOey6cmr9MhC2kma1VCwE%2FRWy5KzcQMsXylqjILyGBN3dmWNpcckKgphjwaZrCv6%2Bj14qGA3EPssZx%2FMJmF%2BZyEnAv455RQ75JLDRuHui2TfWdgBWdbQgj8n4v9JZE3xBHtSpi%2Fca3cjIeIeraXcxOwQ%2FZ4qD5CrsK5wh%2F0qzbEvpnKnhtM%7Ctkp%3ABk9SR4SNjeuyZw
A14: PA06 | B14: Control | C14: Vinted | D14: =Products!G58 | E14: 70 | F14: =IFERROR(IF(AND(D14<>"",E14<>""),E14/D14,""),"") | H14: Very Good | J14: https://www.vinted.it/items/8088494719-cappotto-lungo-nero-mango-x-manteco-72-lana-taglia-m?referrer=catalog
A15: PA07 | K15: CAN'T FIND IT
A16: PA07
A17: PA08
A18: PA08
A19: PA09
A20: PA09
A21: PA10
A22: PA10
A23: PA11 | B23: Manteco | C23: Vestiaire Collective | D23: 299 | E23: 179 | F23: =IFERROR(IF(AND(D23<>"",E23<>""),E23/D23,""),"") | H23: Excellent | J23: https://it.vestiairecollective.com/donna-abbigliamento/cappotti/cos/cappotti-cos-marina-lana-62870779.shtml
A24: PA11 | B24: Control | C24: Vinted | D24: 299 | E24: 155 | F24: =IFERROR(IF(AND(D24<>"",E24<>""),E24/D24,""),"") | H24: Excellent | J24: https://www.vinted.co.uk/items/7752876217-cos-oversized-double-breasted-wool-coat?utm_source=chatgpt.com
A25: PA12
A26: PA12
A27: PA13 | B27: Manteco | C27: Vestiaire Collective | D27: 1320 | E27: 611 | F27: =IFERROR(IF(AND(D27<>"",E27<>""),E27/D27,""),"") | H27: Very Good | J27: https://it.vestiairecollective.com/donna-abbigliamento/cappotti/woolrich/cappotti-woolrich-marina-lana-50801474.shtml
A28: PA13
A29: PA14
A30: PA15 | B30: Manteco | C30: eBay | D30: 378 | E30: 100 | F30: =IFERROR(IF(AND(D30<>"",E30<>""),E30/D30,""),"") | H30: Very Good | J30: https://www.ebay.com/itm/157808806245?_skw=aritzia+double+faced&itmmeta=01KPJHZ9VW4R7VG3D7Q7QZPSTM&hash=item24be234965:g:SbkAAeSwqiRp0cK0&itmprp=enc%3AAQALAAAA0GfYFPkwiKCW4ZNSs2u11xD3xp3nXUpG%2F3XVNGuU12cRgt8ThOQ%2FBoAM5yh6cVDA86jTTueR9AiY1jAOK3F%2FoCv7b5GiRqi2Zw7DekaA7bCKi5KVfkQry6zXnM5rJsGxy5scQ8xn%2FkKF%2F3X4MBsaOYclvbcmjhRg6PGEnRbSFnXnwivZiZ6nSSvj%2B2kAih9kUL0XEAoD71WuN73SXlWDj%2BrFPyQnsGPfUt%2FuWOHu11Qm2pon01GCVGOdBkTH7oUWqUBa7tNvRtIuWllfazuMR9Y%3D%7Ctkp%3ABk9SR5Ce_dG0Zw
A31: PA15 | F31: =IFERROR(IF(AND(D31<>"",E31<>""),E31/D31,""),"")
A32: PA16 | F32: =IFERROR(IF(AND(D32<>"",E32<>""),E32/D32,""),"")
A33: PA17 | F33: =IFERROR(IF(AND(D33<>"",E33<>""),E33/D33,""),"")
A34: PA17 | F34: =IFERROR(IF(AND(D34<>"",E34<>""),E34/D34,""),"")
A35: PA18 | F35: =IFERROR(IF(AND(D35<>"",E35<>""),E35/D35,""),"")
A36: PA18 | F36: =IFERROR(IF(AND(D36<>"",E36<>""),E36/D36,""),"")
A37: PA19 | F37: =IFERROR(IF(AND(D37<>"",E37<>""),E37/D37,""),"")
A38: PA19 | F38: =IFERROR(IF(AND(D38<>"",E38<>""),E38/D38,""),"")
A39: PA20
A40: PA20
...

Sheet Summary
A1: MANTECO PRICE RESILIENCE — Research Summary
A2: Baruch College & Free University of Bozen-Bolzano · March 2026
A4: "Garments incorporating Manteco fabrics demonstrate stronger price resilience across their lifecycle than comparable garments without the Manteco label. Benchmark: ≥10% differential."
B6: Products in Library | C6: Pairs Matched | D6: Avg Retail Premium | E6: Avg MD Delta | F6: Pairs ≥10% | G6: Data Completeness
B7: =COUNTA(Products!C3:C101) | C7: =COUNTA('Matched Pairs'!B3:B52) | D7: =IFERROR(AVERAGEIF('Matched Pairs'!K3:K52,"<>"),"—") | E7: =IFERROR(AVERAGEIF(Markdown!I3:I52,"<>"),"—") | F7: =COUNTIF('Matched Pairs'!K3:K52,">="&0.1) | G7: =IFERROR(COUNTIF('Matched Pairs'!K3:K52,"<>")/COUNTA('Matched Pairs'!B3:B52),"—")
B9: =IF(D7="—","⏳ Pending — add more data","" & IF(ISNUMBER(D7),IF(D7>=0.1,"✓ SUPPORTED — "&TEXT(D7,"0.0%")&" avg premium exceeds 10% benchmark","✗ BELOW THRESHOLD — "&TEXT(D7,"0.0%")&" avg premium"),"⏳ Pending"))
B11: LIFECYCLE STAGE RESULTS
B12: Stage 2 — Market Entry | D12: Retail Premium % | F12: =IFERROR(AVERAGEIF('Matched Pairs'!K3:K52,"<>"),"—")
B13: Stage 3 — Markdown Depth | D13: MD Differential (pp) | F13: =IFERROR(AVERAGEIF(Markdown!I3:I52,"<>"),"—")
B14: Stage 4 — Secondary Market | D14: Avg Residual % | F14: =IFERROR(AVERAGEIF(Resale!F3:F203,"<>"),"—")
B16: HOW TO USE THIS WORKBOOK
B17: 1 Products | D17: Enter every product (Manteco or Control). Use the Type dropdown. Blue = your input, grey = auto-calc.
B18: 2 Matched Pairs | D18: Enter brand + tier. Type the Manteco Product ID and Control Product ID. Retail prices pull automatically.
B19: 3 Markdown | D19: When items go on sale, enter sale prices in columns D and G. Markdown % and delta calculate automatically.
B20: 4 Resale | D20: Log each resale listing you find. Enter pair ID, side, platform, original retail, and resale price.
B21: 5 This tab | D21: All KPIs update live. The verdict bar will turn green once average premium reaches 10%.
